2022-01-19 15:20:02,486 INFO    MainThread:15848 [wandb_setup.py:_flush():71] setting env: {}
2022-01-19 15:20:02,486 INFO    MainThread:15848 [wandb_setup.py:_flush():71] setting login settings: {}
2022-01-19 15:20:02,487 INFO    MainThread:15848 [wandb_init.py:_log_setup():371] Logging user logs to C:\Users\USER\PycharmProjects\DL_project\vit_att_trial\wandb\run-20220119_152002-1lgq1150\logs\debug.log
2022-01-19 15:20:02,488 INFO    MainThread:15848 [wandb_init.py:_log_setup():372] Logging internal logs to C:\Users\USER\PycharmProjects\DL_project\vit_att_trial\wandb\run-20220119_152002-1lgq1150\logs\debug-internal.log
2022-01-19 15:20:02,490 INFO    MainThread:15848 [wandb_init.py:init():404] calling init triggers
2022-01-19 15:20:02,502 INFO    MainThread:15848 [wandb_init.py:init():411] wandb.init called with sweep_config: {}
config: {}
2022-01-19 15:20:02,503 INFO    MainThread:15848 [wandb_init.py:init():460] starting backend
2022-01-19 15:20:02,504 INFO    MainThread:15848 [backend.py:_multiprocessing_setup():101] multiprocessing start_methods=spawn, using: spawn
2022-01-19 15:20:02,514 INFO    MainThread:15848 [backend.py:ensure_launched():216] starting backend process...
2022-01-19 15:20:03,046 INFO    MainThread:15848 [backend.py:ensure_launched():222] started backend process with pid: 9560
2022-01-19 15:20:03,046 INFO    MainThread:15848 [wandb_init.py:init():469] backend started and connected
2022-01-19 15:20:03,050 INFO    MainThread:15848 [wandb_init.py:init():533] updated telemetry
2022-01-19 15:20:03,188 INFO    MainThread:15848 [wandb_init.py:init():563] communicating current version
2022-01-19 15:20:04,657 INFO    MainThread:15848 [wandb_init.py:init():568] got version response 
2022-01-19 15:20:04,657 INFO    MainThread:15848 [wandb_init.py:init():578] communicating run to backend with 30 second timeout
2022-01-19 15:20:05,525 INFO    MainThread:15848 [wandb_init.py:init():606] starting run threads in backend
2022-01-19 15:20:06,175 INFO    MainThread:15848 [wandb_run.py:_console_start():1810] atexit reg
2022-01-19 15:20:06,177 INFO    MainThread:15848 [wandb_run.py:_redirect():1684] redirect: SettingsConsole.WRAP
2022-01-19 15:20:06,177 INFO    MainThread:15848 [wandb_run.py:_redirect():1721] Wrapping output streams.
2022-01-19 15:20:06,179 INFO    MainThread:15848 [wandb_run.py:_redirect():1745] Redirects installed.
2022-01-19 15:20:06,179 INFO    MainThread:15848 [wandb_init.py:init():633] run started, returning control to user process
2022-01-19 15:25:42,993 INFO    MainThread:15848 [wandb_run.py:_atexit_cleanup():1780] got exitcode: 1
2022-01-19 15:25:43,087 INFO    MainThread:15848 [wandb_run.py:_restore():1752] restore
2022-01-19 15:25:47,235 ERROR   MainThread:15848 [wandb_run.py:_atexit_cleanup():1798] Problem finishing run
Traceback (most recent call last):
  File "C:\Users\USER\PycharmProjects\DL_project\venv\lib\site-packages\wandb\sdk\wandb_run.py", line 1788, in _atexit_cleanup
    self._on_finish()
  File "C:\Users\USER\PycharmProjects\DL_project\venv\lib\site-packages\wandb\sdk\wandb_run.py", line 1934, in _on_finish
    self.history._flush()
  File "C:\Users\USER\PycharmProjects\DL_project\venv\lib\site-packages\wandb\sdk\wandb_history.py", line 59, in _flush
    self._callback(row=self._data, step=self._step)
  File "C:\Users\USER\PycharmProjects\DL_project\venv\lib\site-packages\wandb\sdk\wandb_run.py", line 1018, in _history_callback
    row, step, publish_step=not_using_tensorboard
  File "C:\Users\USER\PycharmProjects\DL_project\venv\lib\site-packages\wandb\sdk\interface\interface.py", line 496, in publish_history
    data = data_types.history_dict_to_json(run, data, step=step)
  File "C:\Users\USER\PycharmProjects\DL_project\venv\lib\site-packages\wandb\sdk\data_types.py", line 2597, in history_dict_to_json
    payload[key] = val_to_json(run, key, val, namespace=step)
  File "C:\Users\USER\PycharmProjects\DL_project\venv\lib\site-packages\wandb\sdk\data_types.py", line 2669, in val_to_json
    art.add(val, key)
  File "C:\Users\USER\PycharmProjects\DL_project\venv\lib\site-packages\wandb\sdk\wandb_artifacts.py", line 520, in add
    with self.new_file(name) as f:
  File "C:\Users\USER\AppData\Local\Programs\Python\Python37\lib\contextlib.py", line 112, in __enter__
    return next(self.gen)
  File "C:\Users\USER\PycharmProjects\DL_project\venv\lib\site-packages\wandb\sdk\wandb_artifacts.py", line 364, in new_file
    with util.fsync_open(path, mode) as f:
  File "C:\Users\USER\AppData\Local\Programs\Python\Python37\lib\contextlib.py", line 112, in __enter__
    return next(self.gen)
  File "C:\Users\USER\PycharmProjects\DL_project\venv\lib\site-packages\wandb\util.py", line 1345, in fsync_open
    with open(path, mode) as f:
FileNotFoundError: [Errno 2] No such file or directory: 'C:\\Users\\USER\\AppData\\Local\\Temp\\tmpbgbc0g5l\\Grads_../res18.table.json'
